<mujoco model="rjax_16">
    <compiler angle="radian" />
    <!-- <option gravity="0 0 0" collision="predefined" timestep="0.002" /> -->
    <option gravity="0 0 -9.81" collision="predefined" timestep="0.002" />
    <!-- <size njmax="500" nconmax="100" /> -->
    <!-- <default>
        <geom solref="0.0002 1" />
    </default> -->
    <default>
        <site type="cylinder" size="0.01 0.03" zaxis="0 1 0" rgba="0.1 0.1 1 .1" />
    </default>
    <asset>
        <mesh name="m_base_link" file="meshes\base_link.stl" scale="0.001 0.001 0.001" />
        <mesh name="m_torso_mid" file="meshes\torso_mid_1.stl" scale="0.001 0.001 0.001" />
        <mesh name="m_s_pitch_l" file="meshes\s_pitch_l_1.stl" scale="0.001 0.001 0.001" />
        <mesh name="m_s_pitch_r" file="meshes\s_pitch_r_1.stl" scale="0.001 0.001 0.001" />
        <mesh name="m_s_adapter_l" file="meshes\s_adapter_l_1.stl" scale="0.001 0.001 0.001" />
        <mesh name="m_main_body" file="meshes\main_body_1.stl" scale="0.001 0.001 0.001" />
        <mesh name="m_s_adapter_r" file="meshes\s_adapter_r_1.stl" scale="0.001 0.001 0.001" />
        <mesh name="m_s_roll_l" file="meshes\s_roll_l_1.stl" scale="0.001 0.001 0.001" />
        <mesh name="m_s_roll_r" file="meshes\s_roll_r_1.stl" scale="0.001 0.001 0.001" />
        <mesh name="m_s_yaw_l" file="meshes\s_yaw_l_1.stl" scale="0.001 0.001 0.001" />
        <mesh name="m_s_yaw_r" file="meshes\s_yaw_r_1.stl" scale="0.001 0.001 0.001" />
        <mesh name="m_end_arm_r" file="meshes\end_arm_r_1.stl" scale="0.001 0.001 0.001" />
        <mesh name="m_end_arm_l" file="meshes\end_arm_l_1.stl" scale="0.001 0.001 0.001" />
        <mesh name="m_leg_adapter_l" file="meshes\leg_adapter_l_1.stl" scale="0.001 0.001 0.001" />
        <mesh name="m_leg_adapter_r" file="meshes\leg_adapter_r_1.stl" scale="0.001 0.001 0.001" />
        <mesh name="m_hip_yaw_l" file="meshes\hip_yaw_l_1.stl" scale="0.001 0.001 0.001" />
        <mesh name="m_hip_yaw_r" file="meshes\hip_yaw_r_1.stl" scale="0.001 0.001 0.001" />
        <mesh name="m_thigh_l" file="meshes\thigh_l_1.stl" scale="0.001 0.001 0.001" />
        <mesh name="m_thigh_r" file="meshes\thigh_r_1.stl" scale="0.001 0.001 0.001" />
        <mesh name="m_calf_l" file="meshes\calf_l_1.stl" scale="0.001 0.001 0.001" />
        <mesh name="m_calf_r" file="meshes\calf_r_1.stl" scale="0.001 0.001 0.001" />
        <mesh name="m_acyl_lo" file="meshes\acyl_lo_1.stl" scale="0.001 0.001 0.001" />
        <mesh name="m_acyl_li" file="meshes\acyl_li_1.stl" scale="0.001 0.001 0.001" />
        <mesh name="m_acyl_ri" file="meshes\acyl_ri_1.stl" scale="0.001 0.001 0.001" />
        <mesh name="m_acyl_ro" file="meshes\acyl_ro_1.stl" scale="0.001 0.001 0.001" />
        <mesh name="m_a_commutator_l" file="meshes\a_commutator_l_1.stl" scale="0.001 0.001 0.001" />
        <mesh name="m_a_commutator_r" file="meshes\a_commutator_r_1.stl" scale="0.001 0.001 0.001" />
        <mesh name="m_foot_l" file="meshes\foot_l_1.stl" scale="0.001 0.001 0.001" />
        <mesh name="m_foot_r" file="meshes\foot_r_1.stl" scale="0.001 0.001 0.001" />
        <mesh name="m_e_cyl_r" file="meshes\e_cyl_r_1.stl" scale="0.001 0.001 0.001" />
        <mesh name="m_e_piston_r" file="meshes\e_piston_r_1.stl" scale="0.001 0.001 0.001" />
        <mesh name="m_e_cyl_l" file="meshes\e_cyl_l_1.stl" scale="0.001 0.001 0.001" />
        <mesh name="m_e_piston_l" file="meshes\e_piston_l_1.stl" scale="0.001 0.001 0.001" />
        <mesh name="m_crank_ri" file="meshes\crank_ri_1.stl" scale="0.001 0.001 0.001" />
        <mesh name="m_tf_ri" file="meshes\tf_ri_1.stl" scale="0.001 0.001 0.001" />
        <mesh name="m_tf_ro" file="meshes\tf_ro_1.stl" scale="0.001 0.001 0.001" />
        <mesh name="m_crank_ro" file="meshes\crank_ro_1.stl" scale="0.001 0.001 0.001" />
        <mesh name="m_crank_lo" file="meshes\crank_lo_1.stl" scale="0.001 0.001 0.001" />
        <mesh name="m_crank_li" file="meshes\crank_li_1.stl" scale="0.001 0.001 0.001" />
        <mesh name="m_tf_lo" file="meshes\tf_lo_1.stl" scale="0.001 0.001 0.001" />
        <mesh name="m_tf_li" file="meshes\tf_li_1.stl" scale="0.001 0.001 0.001" />
        <mesh name="m_a_piston_li" file="meshes\a_piston_li_1.stl" scale="0.001 0.001 0.001" />
        <mesh name="m_a_piston_lo" file="meshes\a_piston_lo_1.stl" scale="0.001 0.001 0.001" />
        <mesh name="m_a_piston_ro" file="meshes\a_piston_ro_1.stl" scale="0.001 0.001 0.001" />
        <mesh name="m_a_piston_ri" file="meshes\a_piston_ri_1.stl" scale="0.001 0.001 0.001" />
        <mesh name="m_k_cyl_l" file="meshes\k_cyl_l_1.stl" scale="0.001 0.001 0.001" />
        <mesh name="m_k_piston_l" file="meshes\k_piston_l_1.stl" scale="0.001 0.001 0.001" />
        <mesh name="m_k_cyl_r" file="meshes\k_cyl_r_1.stl" scale="0.001 0.001 0.001" />
        <mesh name="m_k_piston_r" file="meshes\k_piston_r_1.stl" scale="0.001 0.001 0.001" />
        <mesh name="m_h_cyl_l" file="meshes\h_cyl_l_1.stl" scale="0.001 0.001 0.001" />
        <mesh name="m_h_piston_l" file="meshes\h_piston_l_1.stl" scale="0.001 0.001 0.001" />
        <mesh name="m_h_cyl_r" file="meshes\h_cyl_r_1.stl" scale="0.001 0.001 0.001" />
        <mesh name="m_h_piston_r" file="meshes\h_piston_r_1.stl" scale="0.001 0.001 0.001" />
    </asset>
    <worldbody>
        <!-- LIGHT -->
        <light name="l_light" diffuse=".5 .5 .5" pos="0 -2 2" dir="0 1 -1" mode="trackcom" target="b_base_link" />
        <!-- PLANE -->
        <body name="b_plane" pos="0 0 -1.984">
            <!-- pos="0 0 -0.99" -->
            <geom name="g_plane" type="plane" size="10 10 0.1" pos="0 0 0" rgba=".3 .3 .3 1" />
        </body>
        <!-- COLLISION BOX -->
        <!-- <body name="b_collision_box" pos="0 0 -1.0">
            <geom name="g_collision_box" type="box" size="0.12 0.12 0.01" rgba=".1 .4 .5 .3" />
        </body> -->
        <!-- BOUNDING BOXES -->
        <!-- <body name="b_box" pos="0 0 -0.1">
            <geom name="g_box" type="box" size="0.372 0.283 0.8752" rgba=".1 .4 .5 .3" />
        </body> -->
        <!-- <body name="new_box" pos="1.5 0 -0.1">
            <geom name="new_g_box" type="box" size="0.372 0.283 0.8752" rgba=".1 .4 .5 .3" />
        </body> -->
        <body mocap="true" name="mocap_wrist_r" pos="-0.27 -0.1 -0.1">
            <geom pos="0 0 0" rgba="0 0.5 0 0.7" size="0.05" type="sphere" />
        </body>
        <!-- <body mocap="true" name="mocap_wrist_l" pos="0.27 -0.1 -0.1">
            <geom pos="0 0 0" rgba="0 0.5 0 0.7" size="0.05" type="sphere" />
        </body> -->
        <!-- <body mocap="true" name="mocap_ankle_point_l" pos="0.15 -0.005 -0.93">
            <geom pos="0 0 0" rgba="0 0.5 0 0.7" size="0.07 0.01 0.01" type="box" />
        </body> -->
        <!-- <body mocap="true" name="mocap_ankle_point_r" pos="-0.15 -0.005 -0.93">
            <geom pos="0 0 0" rgba="0 0.5 0 0.7" size="0.07 0.01 0.01" type="box" />
        </body> -->
        <!-- <body mocap="true" name="mocap_elbow_point_r" pos="-0.27 0 0.2">
            <geom pos="0 0 0" rgba="0 0.5 0 0.7" size="0.07 0.07 0.07" type="box" />
        </body> -->
        <!-- <body mocap="true" name="mocap_elbow_point_l" pos="0.27 0 0.2">
            <geom pos="0 0 0" rgba="0 0.5 0 0.7" size="0.07 0.07 0.07" type="box" />
        </body> -->

        <!-- ROBOT -->
        <body name="b_base_link" pos="0 0 0">
            <!-- <joint name="j_base_link" type="free" /> -->
            <geom name="g_base_link" type="mesh" mesh="m_base_link" />
            <body name="b_torso_mid" pos="0 -0.000423 0.09483">
                <inertial pos="-0.00199358 0.0015583 0.0684747" quat="0.462279 0.885447 -0.00925238 0.0468584" mass="1.42697" diaginertia="0.00433823 0.00328022 0.00317154" />
                <joint name="j_TYaw" pos="0 0 0" axis="0 -0.087156 0.996195" type="hinge" limited="true" range="-0.78539 0.78539" damping="30" />
                <geom name="g_torso_mid" pos="0 0.000423 -0.09483" type="mesh" mesh="m_torso_mid" />
                <geom name="g_force_render_tYaw" pos="0 0 0" euler="0.0872665 0 0" type="cylinder" size="0.01 0.01" rgba="1 0 0 1" mass="0.000001" />
                <body name="b_main_body" pos="0 -0.074253 0.062767">
                    <inertial pos="4.72919e-05 0.105093 0.278369" quat="0.997962 0.0638084 -0.000450933 -0.000225579" mass="51.3948" diaginertia="1.28965 0.944327 0.746389" />
                    <joint name="j_TRoll" pos="0 0 0" axis="0 -0.996195 -0.087156" type="hinge" limited="true" range="-0.08 0.08" damping="30" />
                    <!-- <joint name="j_TRoll" pos="0 0 0" axis="0 -0.996195 -0.087156" type="hinge" limited="true" range="-0.65449 0.65449" damping="30" /> -->
                    <geom name="g_force_render_tRoll" pos="0 0 0" euler="1.6580628 0 0" type="cylinder" size="0.01 0.01" rgba="1 0 0 1" mass="0.000001" />
                    <geom name="g_main_body" pos="0 0.074676 -0.157597" type="mesh" mesh="m_main_body" />
                    <geom name="g_s_pitch_l" pos="0 0.074676 -0.157597" type="mesh" mesh="m_s_pitch_l" />
                    <geom name="g_s_pitch_r" pos="0 0.074676 -0.157597" type="mesh" mesh="m_s_pitch_r" />
                    <body name="b_s_adapter_l" pos="0.203976 0.051541 0.496393">
                        <inertial pos="0.04692 -0.00030179 -0.00625393" quat="0.497855 0.563093 -0.49113 0.440293" mass="0.699962" diaginertia="0.0054197 0.00505806 0.00161023" />
                        <joint name="j_SPitch_L" pos="0 0 0" axis="0.991445 0.015085 -0.129652" type="hinge" limited="true" range="-1.57079 1.57079" damping="30" />
                        <geom name="g_s_adapter_l" pos="-0.203976 0.023135 -0.65399" type="mesh" mesh="m_s_adapter_l" />
                        <geom name="g_force_render_sPitch_l" pos="0 0 0" euler="0 1.75 0" type="cylinder" size="0.01 0.01" rgba="1 0 0 1" mass="0.000001" />
                        <body name="b_s_roll_l" pos="0.084272 0.089685 -0.000735">
                            <inertial pos="0.00456335 -0.0838442 -0.0368111" quat="0.677046 0.727983 -0.0771344 0.075497" mass="2.2438" diaginertia="0.0100802 0.00814454 0.00630426" />
                            <joint name="j_SRoll_L" pos="0 0 0" axis="0 -0.993299 -0.115571" type="hinge" limited="true" range="-0.20944 2.094395" damping="30" />
                            <geom name="g_s_roll_l" pos="-0.288248 -0.06655 -0.653255" type="mesh" mesh="m_s_roll_l" />
                            <geom name="g_force_render_sRoll_l" pos="0 0 0" euler="1.7 0 0" type="cylinder" size="0.01 0.01" rgba="1 0 0 1" mass="0.000001" />
                            <body name="b_s_yaw_l" pos="0.008917 -0.074769 -0.103675">
                                <inertial pos="-0.00496756 -0.00428128 -0.115401" quat="0.767115 -0.00433749 0.032373 0.640678" mass="2.05459" diaginertia="0.0185103 0.0184774 0.00589828" />
                                <joint name="j_SYaw_L" pos="0 0 0" axis="0.043619 -0.115461 0.992354" type="hinge" limited="true" range="-0.87266 0.87266" damping="30" />
                                <geom name="g_s_yaw_l" pos="-0.297165 0.008219 -0.54958" type="mesh" mesh="m_s_yaw_l" />
                                <geom name="g_force_render_sYaw_l" pos="0 0 0" euler="0.12 0 0" type="cylinder" size="0.01 0.01" rgba="1 0 0 1" mass="0.000001" />
                                <body name="b_weld_epitch_l" pos="-0.014689 -0.012067 -0.329581">
                                    <!-- x: -0.01 -0.001222 -0.003467 = -0.014689-->
                                    <!-- y: 0.0536 + 0.004618 + -0.070285 = -0.012067 -->
                                    <!-- z: -0.2138 -0.027643 -0.088138 = -0.329581 -->
                                    <!-- -0.01     0.0536    -0.2138 -->
                                    <!-- -0.001222 0.004618  -0.027643 -->
                                    <!-- -0.003467 -0.070285 -0.088138 -->
                                    <joint name="j_EPitch_L" type="hinge" axis="0.999048 0.005041 -0.043327" limited="true" range="-0.35159 1.61376" />
                                    <geom name="g_weld_epitch_l" type="box" size=".01 .02 .03" rgba="0 1 1 1" mass="0.000001" />
                                </body>
                                <body name="b_e_cyl_l" pos="-0.003467 -0.070285 -0.088138">
                                    <inertial pos="-0.00403006 0.00870966 -0.0929502" quat="0.982472 0.185075 0.0222863 -0.000165253" mass="0.231148" diaginertia="0.00106668 0.000950452 0.000190864" />
                                    <joint name="j_Rev65_e_cyl_l" pos="0 0 0" axis="0.999048 0.005041 -0.043327" type="hinge" />
                                    <geom name="g_e_cyl_l" pos="-0.293698 0.078504 -0.461442" type="mesh" mesh="m_e_cyl_l" rgba="0 0 0.5 0.3" />
                                    <site name="e_cyl_l_s" zaxis="0 0 1" />
                                    <body name="b_e_piston_l" pos="-0.001222 0.004618 -0.027643">
                                        <inertial pos="-0.00626674 0.013857 -0.140145" quat="0.97977 0.043918 0.0328264 -0.19247" mass="0.0867848" diaginertia="0.000307826 0.000306721 1.14526e-05" />
                                        <joint name="j_E_LIN_L" pos="0 0 0" axis="0.043613 -0.098326 0.994198" type="slide" limited="true" range="-0.010 0.05710" damping="30" />
                                        <geom name="g_e_piston_l" pos="-0.292476 0.073886 -0.433799" type="mesh" mesh="m_e_piston_l" />
                                        <body name="b_end_arm_l" pos="-0.01 0.0536 -0.2138">
                                            <inertial pos="-0.00377304 -0.0347714 -0.0910382" quat="0.695186 -0.104082 0.132951 0.698719" mass="0.297497" diaginertia="0.00257635 0.00253151 0.000266139" />
                                            <joint name="j_EPitch_joint_L" pos="0.0 -0.03 -0.027" axis="0.999048 0.005041 -0.043327" type="hinge" />
                                            <geom name="g_end_arm_l" pos="-0.282924 0.020186 -0.219798" type="mesh" mesh="m_end_arm_l" rgba="1 0 0 .5" />
                                            <!-- <body name="b_weld_epitch_l" pos="0 0 0">
                                                <joint name="j_EPitch_L" type="hinge" axis="0.999048 0.005041 -0.043327" limited="true" range="-0.35159 1.61376"/>
                                                <geom name="g_weld_epitch_l" type="box" size=".01 .02 .03" rgba="0 1 1 1" mass="0.000001" />
                                            </body> -->
                                        </body>
                                    </body>
                                </body>
                            </body>
                        </body>
                    </body>
                    <body name="b_s_adapter_r" pos="-0.203976 0.051541 0.496393">
                        <inertial pos="-0.0370055 -0.000452641 -0.00495741" quat="0.440293 0.49113 -0.563093 0.497855" mass="0.699962" diaginertia="0.0054197 0.00505806 0.00161023" />
                        <joint name="j_SPitch_R" pos="0 0 0" axis="-0.991445 0.015085 -0.129652" type="hinge" limited="true" range="-1.57079 1.57079" damping="30" />
                        <geom name="g_s_adapter_r" pos="0.203976 0.023135 -0.65399" type="mesh" mesh="m_s_adapter_r" />
                        <geom name="g_force_render_sPitch_r" pos="0 0 0" euler="0 -1.75 0" type="cylinder" size="0.01 0.01" rgba="1 0 0 1" mass="0.000001" />
                        <body name="b_s_roll_r" pos="-0.074358 0.089535 0.000562">
                            <inertial pos="-0.00456214 -0.0839035 -0.0368096" quat="0.677356 0.727663 0.077195 -0.075737" mass="2.24458" diaginertia="0.0100916 0.00815495 0.00630345" />
                            <joint name="j_SRoll_R" pos="0 0 0" axis="0 -0.993299 -0.115571" type="hinge" limited="true" range="-2.094395 0.20944" damping="30" />
                            <geom name="g_s_roll_r" pos="0.278334 -0.0664 -0.654552" type="mesh" mesh="m_s_roll_r" />
                            <geom name="g_force_render_sRoll_r" pos="0 0 0" euler="1.7 0 0" type="cylinder" size="0.01 0.01" rgba="1 0 0 1" mass="0.000001" />
                            <body name="b_s_yaw_r" pos="-0.008917 -0.07477 -0.103675">
                                <inertial pos="0.0049883 -0.00445212 -0.115189" quat="0.775146 -0.0323107 -0.000799129 0.630955" mass="2.05126" diaginertia="0.0184676 0.0184369 0.00588456" />
                                <joint name="j_SYaw_R" pos="0 0 0" axis="-0.043619 -0.115461 0.992354" type="hinge" limited="true" range="-0.87266 0.87266" damping="30" />
                                <geom name="g_s_yaw_r" pos="0.287251 0.00837 -0.550877" type="mesh" mesh="m_s_yaw_r" />
                                <geom name="g_force_render_sYaw_r" pos="0 0 0" euler="0.12 0 0" type="cylinder" size="0.01 0.01" rgba="1 0 0 1" mass="0.000001" />
                                <body name="b_weld_epitch_r" pos="0.014689 -0.012067 -0.329581">
                                    <joint name="j_EPitch_R" type="hinge" axis="0.999048 -0.005041 0.043327" limited="true" range="-0.35159 1.61376" />
                                    <geom name="g_weld_epitch_r" type="box" size=".01 .02 .03" rgba="0 1 1 1" mass="0.000001" />
                                </body>
                                <body name="b_e_cyl_r" pos="0.003468 -0.070284 -0.088138">
                                    <inertial pos="0.00411998 0.00870934 -0.0929466" quat="0.982497 0.185063 -0.0212049 0.0012667" mass="0.231148" diaginertia="0.0010665 0.000950448 0.000191053" />
                                    <joint name="j_Rev62_e_cyl_r" pos="0 0 0" axis="0.999048 -0.005041 0.043327" type="hinge" />
                                    <geom name="g_e_cyl_r" pos="0.283783 0.078654 -0.462739" type="mesh" mesh="m_e_cyl_r" rgba="0 0 0.5 0.3" />
                                    <!-- <site name="e_cyl_r_s" zaxis="0 0 1" /> -->
                                    <body name="b_e_piston_r" pos="0.001222 0.004618 -0.027643">
                                        <inertial pos="0.00602968 0.0138591 -0.140156" quat="0.98893 0.046147 -0.0270509 0.138409" mass="0.0867848" diaginertia="0.000307546 0.000306826 1.16279e-05" />
                                        <joint name="j_E_LIN_R" pos="0 0 0" axis="-0.043613 -0.098336 0.994197" type="slide" limited="true" range="-0.010 0.05710" damping="30" />
                                        <geom name="g_e_piston_r" pos="0.282561 0.074036 -0.435096" type="mesh" mesh="m_e_piston_r" />
                                        <body name="b_end_arm_r" pos="0.01 0.0536 -0.2138">
                                            <!-- pos="-0.01 0.0536 -0.2138" -->
                                            <inertial pos="0.00377249 -0.0347723 -0.0910387" quat="0.698719 -0.132951 0.104082 0.695186" mass="0.297497" diaginertia="0.00257635 0.00253151 0.000266139" />
                                            <joint name="j_EPitch_joint_R" pos="0.0 -0.03 -0.027" axis="0.999048 -0.005041 0.043327" type="hinge" />
                                            <geom name="g_end_arm_r" pos="0.273009 0.020336 -0.221095" type="mesh" mesh="m_end_arm_r" rgba="1 0 0 .4" />
                                        </body>
                                    </body>
                                </body>
                            </body>
                        </body>
                    </body>
                </body>
            </body>
            <body name="b_leg_adapter_l" pos="0.09 -0.07925 0">
                <inertial pos="0.0459047 0.0956187 -0.045765" quat="0.637983 0.655217 -0.282873 0.289224" mass="1.2509" diaginertia="0.0054821 0.00521852 0.00282238" />
                <joint name="j_HRoll_L" pos="0 0 0" axis="0 -1 0" type="hinge" limited="true" range="-0.52359 0.78539" damping="30" />
                <geom name="g_leg_adapter_l" pos="-0.09 0.07925 0" type="mesh" mesh="m_leg_adapter_l" />
                <geom name="g_force_render_HRoll_l" pos="0 0 0" euler="1.5707963 0 0" type="cylinder" size="0.01 0.01" rgba="1 0 0 1" mass="0.000001" />
                <body name="b_hip_yaw_l" pos="0.053995 0.1085 -0.098995">
                    <inertial pos="0.000177646 -0.00999044 -0.0693225" quat="0.938251 0.345828 -0.00179383 -0.00920583" mass="1.64067" diaginertia="0.00614039 0.00537967 0.00412594" />
                    <joint name="j_HYaw_L" pos="0 0 0" axis="0 0 1" type="hinge" limited="true" range="-0.43633 0.43633" damping="30" />
                    <geom name="g_hip_yaw_l" pos="-0.143995 -0.02925 0.098995" type="mesh" mesh="m_hip_yaw_l" rgba="0 0 1 .2" />
                    <geom name="g_force_render_HYaw_l" pos="0 0 0" euler="0 0 0" type="cylinder" size="0.01 0.01" rgba="1 0 0 1" mass="0.000001" />
                    <body name="b_h_piston_l" pos="0 -0.089 -0.328">
                        <inertial pos="-5.77882e-05 -0.0181295 0.171191" quat="0.998065 0.0524707 -0.00239759 0.0332732" mass="0.149647" diaginertia="0.000796008 0.000794431 2.75603e-05" />
                        <joint name="j_Rev88_h_cyl_l" pos="0 -0.032 0.298" axis="1 0 0" type="hinge" />
                        <geom name="g_h_piston_l" pos="-0.144495 0.0597 0.427256" type="mesh" mesh="m_h_piston_l" />
                        <body name="b_h_cyl_l" pos="0 0.00495 -0.046739">
                            <!-- pos="-0.0545 -0.05 -0.32" -->
                            <inertial pos="-0.000226962 -0.0195357 0.115677" quat="0.997923 0.0627685 0.00397027 -0.0139205" mass="0.325584" diaginertia="0.00201416 0.00189518 0.000287654" />
                            <joint name="j_H_LIN_L" pos="0 0 0" axis="0 -0.10531 0.994439" type="slide" limited="true" range="-0.0905355 0.0151645" damping="30" />
                            <geom name="g_h_cyl_l" pos="-0.144495 0.05475 0.473995" type="mesh" mesh="m_h_cyl_l" rgba="0 0 0.5 0.3" />
                            <body name="b_thigh_l" pos="0.0545 0.05 0.32">
                                <inertial pos="-0.0545001 -0.0199022 -0.178756" quat="0.70582 -0.0426418 0.0426418 0.70582" mass="1.91939" diaginertia="0.0232006 0.020492 0.00736143" />
                                <joint name="j_Rev89_h_cyl_l" pos="-0.0545 -0.05 -0.32" axis="1 0 0" type="hinge" />
                                <geom name="g_thigh_l" pos="-0.198995 0.00475 0.153995" type="mesh" mesh="m_thigh_l" />
                                <body name="b_knee_pitch_weld_l" pos="-0.0545 0 -0.375">
                                    <joint name="j_Knee_L" pos="0 0 0" axis="1 0 0" type="hinge" />
                                    <geom name="g_knee_pitch_weld_l" type="box" size=".01 .02 .03" rgba="0 1 1 .1" mass="0.000001" />
                                </body>
                                <body name="b_weld_h_pitch_l">
                                    <joint name="j_HPitch_L" type="hinge" axis="1 0 0" />
                                    <geom name="g_weld_h_pitch_l" type="box" size=".01 .02 .03" rgba="0 1 1 .1" mass="0.000001" />
                                </body>
                                <body name="b_k_cyl_l" pos="-0.0545 -0.002 -0.125">
                                    <inertial pos="-2.97235e-05 0.0206875 -0.0956294" quat="0.996629 0.0820395 -0.000559422 0.000733071" mass="0.285911" diaginertia="0.001237 0.0011317 0.000245296" />
                                    <joint name="j_Rev84_k_cyl_l" pos="0 0 0" axis="-1 0 0" type="hinge" />
                                    <geom name="g_k_cyl_l" pos="-0.144495 0.00675 0.278995" type="mesh" mesh="m_k_cyl_l" rgba="0 0 0.5 0.3" />
                                    <body name="b_k_piston_l" pos="0 0.006587 -0.046536">
                                        <inertial pos="-6.50458e-05 0.0201422 -0.142346" quat="0.996856 0.0697515 0.00379265 -0.0373886" mass="0.126617" diaginertia="0.000447013 0.000445151 2.48358e-05" />
                                        <joint name="j_K_LIN_L" pos="0 0 0" axis="0 -0.140141 0.990132" type="slide" limited="true" range="-0.077441 0.0" />
                                        <geom name="g_k_piston_l" pos="-0.144495 0.000163 0.325531" type="mesh" mesh="m_k_piston_l" />
                                        <body name="b_calf_l" pos="0 -0.004587 -0.203464">
                                            <!-- pos="-0.0545 0 -0.375" -->
                                            <inertial pos="-3.93606e-05 -0.0104904 -0.134459" quat="0.706684 0.0199592 -0.0201719 0.70696" mass="1.72048" diaginertia="0.0250869 0.023294 0.00586012" />
                                            <joint name="j_knee_piston_conn_l" pos="0 0.039 -0.038" axis="1 0 0" type="hinge" />
                                            <geom name="g_calf_l" pos="-0.144495 0.00475 0.528995" type="mesh" mesh="m_calf_l" rgba="1 1 1 .1" />
                                            <body name="b_acyl_lo" pos="0.0205 -0.03 -0.06">
                                                <inertial pos="-1.4807e-05 0.0247397 -0.0673517" quat="0.996501 -0.0835866 0 0" mass="0.128787" diaginertia="0.000369 0.000268055 0.000121945" />
                                                <joint name="j_Rev26_acyl_lo" pos="0 0 0" axis="-1 0 0" type="hinge" />
                                                <geom name="g_acyl_lo" pos="-0.164995 0.03475 0.588995" type="mesh" mesh="m_acyl_lo" rgba="0 0 0.5 0.3" />
                                                <body name="b_a_piston_lo" pos="0 0.002203 -0.032425">
                                                    <inertial pos="5.41891e-05 0.00522387 -0.0768887" quat="0.999465 0.032701 0 0" mass="0.0378377" diaginertia="8e-05 7.93275e-05 2.67246e-06" />
                                                    <joint name="j_APITCH_LO" pos="0 0 0" axis="0 -0.067772 0.997701" type="slide" limited="true" range="-0.0265 0.0084" damping="30" />
                                                    <!-- Found max APITCH_L range= "-0.802087 0.413268" -->
                                                    <!-- Cylinder Range: range="-0.0265 0.0084" -->
                                                    <geom name="g_a_piston_lo" pos="-0.164995 0.032547 0.62142" type="mesh" mesh="m_a_piston_lo" />
                                                    <body name="b_crank_lo" pos="0 0.051958 -0.157575">
                                                        <!-- pos="0.0205 0.024161 -0.25" -->
                                                        <inertial pos="-5.06345e-08 -0.0363894 -0.000874521" quat="0.671365 0.741127 0 0" mass="0.0576547" diaginertia="7.6e-05 7.35941e-05 1.24059e-05" />
                                                        <joint name="j_Rev76_crank_lo" pos="0 -0.0423 0.0154" axis="1 0 0" type="hinge" />
                                                        <geom name="g_crank_lo" pos="-0.164995 -0.019411 0.778995" type="mesh" mesh="m_crank_lo" />
                                                        <body name="b_crank_weld_lo" pos="0 0 0">
                                                            <joint name="j_crank_weld_lo" pos="0 0 0" axis="1 0 0" type="hinge" />
                                                            <geom name="g_crank_weld_lo" type="box" size=".01 .02 .03" rgba="0 1 1 .1" mass="0.000001" />
                                                        </body>
                                                        <body name="b_inner_weld_tf_lo" pos="0 -0.089434 -0.010081">
                                                            <joint name="j_inner_weld_tf_lo" type="hinge" axis="1 0 0" />
                                                            <geom name="g_inner_weld_tf_lo" type="sphere" size="0.01" rgba=" 0 1 0 .4" />
                                                            <body name="b_tf_lo" pos="0 0 0">
                                                                <inertial pos="-5.02339e-08 -0.00232074 -0.0699611" quat="0.999844 -0.0176465 0 0" mass="0.0807558" diaginertia="0.000213 0.000207247 8.75283e-06" />
                                                                <joint name="j_Rev78_tf_lo" pos="0 0 0" type="hinge" axis="0 1 0" />
                                                                <geom name="g_tf_lo" pos="-0.164995 0.070023 0.789076" type="mesh" mesh="m_tf_lo" />
                                                                <body name="b_outer_weld_tf_lo" pos="0 -0.0047 -0.14">
                                                                    <joint name="j_outer_weld_tf_lo" type="hinge" axis="0 -1 0" />
                                                                    <geom name="g_outer_weld_tf_lo" type="sphere" size="0.01" rgba=" 0 1 0 .4" />
                                                                    <!-- <geom name="g_weld_tf_lo" pos="0 0 0" euler="0 1.57 0" type="cylinder" size="0.01 0.02" rgba=" 0 1 0 .4" /> -->
                                                                    <body name="b_weld_tf_lo" pos="0 0 0">
                                                                        <joint name="j_weld_tf_lo" type="hinge" axis="1 0 0" />
                                                                        <geom name="g_weld_tf_lo" type="sphere" size="0.01" rgba=" 0 1 0 .4" />
                                                                        <!-- <geom name="g_weld_tf_lo" pos="0 0 0" euler="0 1.57 0" type="cylinder" size="0.01 0.02" rgba=" 0 1 0 .4" /> -->
                                                                    </body>
                                                                </body>
                                                            </body>
                                                        </body>
                                                    </body>
                                                </body>
                                            </body>
                                            <body name="b_acyl_li" pos="-0.0205 -0.03 -0.06">
                                                <inertial pos="-1.4807e-05 0.0247397 -0.0673517" quat="0.996501 -0.0835866 0 0" mass="0.128787" diaginertia="0.000369 0.000268055 0.000121945" />
                                                <joint name="j_Rev27_acyl_li" pos="0 0 0" axis="-1 0 0" type="hinge" />
                                                <geom name="g_acyl_li" pos="-0.123995 0.03475 0.588995" type="mesh" mesh="m_acyl_li" rgba="0 1 1 0.3" />
                                                <body name="b_a_piston_li" pos="0 0.002203 -0.032425">
                                                    <inertial pos="5.41891e-05 0.00522387 -0.0768887" quat="0.999465 0.032701 0 0" mass="0.0378377" diaginertia="8e-05 7.93275e-05 2.67246e-06" />
                                                    <joint name="j_APITCH_LI" pos="0 0 0" axis="0 -0.067772 0.997701" type="slide" limited="true" range="-0.0265 0.0084" damping="30" />
                                                    <!-- Found max APITCH_L range= "-0.802087 0.413268" -->
                                                    <!-- Cylinder Range: range="-0.0265 0.0084" -->
                                                    <geom name="g_a_piston_li" pos="-0.123995 0.032547 0.62142" type="mesh" mesh="m_a_piston_li" />
                                                    <body name="b_crank_li" pos="0 0.051958 -0.157575">
                                                        <!-- pos="-0.0205 0.024161 -0.25" -->
                                                        <inertial pos="-5.06345e-08 -0.0363894 -0.000874521" quat="0.671365 0.741127 0 0" mass="0.0576547" diaginertia="7.6e-05 7.35941e-05 1.24059e-05" />
                                                        <joint name="j_Rev77_crank_li" pos="0 -0.0423 0.0154" axis="-1 0 0" type="hinge" />
                                                        <geom name="g_crank_li" pos="-0.123995 -0.019411 0.778995" type="mesh" mesh="m_crank_li" />
                                                        <body name="b_crank_weld_li" pos="0 0 0">
                                                            <joint name="j_crank_weld_li" pos="0 0 0" axis="-1 0 0" type="hinge" />
                                                            <geom name="g_crank_weld_li" type="box" size=".01 .02 .03" rgba="0 1 1 .1" mass="0.000001" />
                                                        </body>
                                                        <body name="b_inner_weld_tf_li" pos="0 -0.089434 -0.010081">
                                                            <joint name="j_inner_weld_tf_li" type="hinge" axis="-1 0 0" />
                                                            <geom name="g_inner_weld_tf_li" type="sphere" size="0.01" rgba=" 0 1 0 .4" />
                                                            <body name="b_tf_li" pos="0 0 0">
                                                                <inertial pos="-5.02339e-08 -0.00232074 -0.0699611" quat="0.999844 -0.0176465 0 0" mass="0.0807558" diaginertia="0.000213 0.000207247 8.75283e-06" />
                                                                <joint name="j_Rev79_tf_li" pos="0 0 0" type="hinge" axis="0 1 0" />
                                                                <geom name="g_tf_li" pos="-0.123995 0.070023 0.789076" type="mesh" mesh="m_tf_li" />
                                                                <body name="b_outer_weld_tf_li" pos="0 -0.0047 -0.14">
                                                                    <joint name="j_outer_weld_tf_li" type="hinge" axis="0 -1 0" />
                                                                    <geom name="g_outer_weld_tf_li" type="sphere" size="0.01" rgba=" 0 1 0 .4" />
                                                                    <!-- <geom name="g_weld_tf_li" pos="0 0 0" euler="0 1.57 0" type="cylinder" size="0.01 0.02" rgba=" 0 1 0 .4" /> -->
                                                                    <body name="b_weld_tf_li" pos="0 0 0">
                                                                        <joint name="j_weld_tf_li" type="hinge" axis="-1 0 0" />
                                                                        <geom name="g_weld_tf_li" type="sphere" size="0.01" rgba=" 0 1 0 .4" />
                                                                        <!-- <geom name="g_weld_tf_li" pos="0 0 0" euler="0 1.57 0" type="cylinder" size="0.01 0.02" rgba=" 0 1 0 .4" /> -->
                                                                    </body>
                                                                </body>
                                                            </body>
                                                        </body>
                                                    </body>
                                                </body>
                                            </body>
                                            <body name="b_a_commutator_l" pos="0 0 -0.4">
                                                <inertial pos="-5.06338e-08 0 5.06339e-08" quat="0 0.707107 0 0.707107" mass="0.0528451" diaginertia="2.7e-05 1.7e-05 1.5e-05" />
                                                <joint name="j_APitch_L" pos="0 0 0" axis="-1 0 0" type="hinge" limited="true" range="-0.802087 0.413268" />
                                                <!-- Found max APITCH_L range= "-0.802087 0.413268" -->
                                                <!-- Full actuated range="-0.802087 0.413268" -->
                                                <geom name="g_a_commutator_l" pos="-0.144495 0.00475 0.928995" type="mesh" mesh="m_a_commutator_l" />
                                                <body name="b_foot_l" pos="0 0 0">
                                                    <inertial pos="0.000690714 -0.0558991 -0.0396183" quat="0.491476 0.5203 -0.512834 0.474068" mass="0.442364" diaginertia="0.00208294 0.00191408 0.000358977" />
                                                    <joint name="j_ARoll_L" pos="0 0 0" axis="0 -1 0" type="hinge" limited="true" range="-0.4 0.4" />
                                                    <geom name="g_foot_l" pos="-0.144495 0.00475 0.928995" type="mesh" mesh="m_foot_l" />
                                                </body>
                                            </body>
                                        </body>
                                    </body>
                                </body>
                            </body>
                        </body>
                    </body>
                </body>
            </body>
            <body name="b_leg_adapter_r" pos="-0.09 -0.07925 0">
                <inertial pos="-0.0459413 0.0956771 -0.045823" quat="0.289831 0.283486 -0.654958 0.637702" mass="1.2566" diaginertia="0.00548365 0.00521997 0.00282638" />
                <joint name="j_HRoll_R" pos="0 0 0" axis="0 -1 0" type="hinge" limited="true" range="-0.78539 0.52359" damping="30" />
                <geom name="g_leg_adapter_r" pos="0.09 0.07925 0" type="mesh" mesh="m_leg_adapter_r" />
                <geom name="g_force_render_HRoll_r" pos="0 0 0" euler="1.5707963 0 0" type="cylinder" size="0.01 0.01" rgba="1 0 0 1" mass="0.000001" />
                <body name="b_hip_yaw_r" pos="-0.053995 0.1085 -0.098995">
                    <inertial pos="0.000177748 -0.00999044 -0.0693225" quat="0.938251 0.345828 -0.00179383 -0.00920583" mass="1.64067" diaginertia="0.00614039 0.00537967 0.00412594" />
                    <joint name="j_HYaw_R" pos="0 0 0" axis="0 0 1" type="hinge" limited="true" range="-0.43633 0.43633" damping="30" />
                    <geom name="g_hip_yaw_r" pos="0.143995 -0.02925 0.098995" type="mesh" mesh="m_hip_yaw_r" rgba="0 0 1 .2" />
                    <geom name="g_force_render_HYaw_r" pos="0 0 0" euler="0 0 0" type="cylinder" size="0.01 0.01" rgba="1 0 0 1" mass="0.000001" />
                    <body name="b_h_piston_r" pos="0 -0.089 -0.328">
                        <!-- pos="0 -0.00495 0.046739" -->
                        <inertial pos="-5.7687e-05 -0.0181295 0.171191" quat="0.998065 0.0524707 -0.00239759 0.0332732" mass="0.149647" diaginertia="0.000796008 0.000794431 2.75603e-05" />
                        <joint name="j_Rev90_h_cyl_r" pos="0 -0.032 0.298" axis="1 0 0" type="hinge" />
                        <geom name="g_h_piston_r" pos="0.144495 0.0597 0.427256" type="mesh" mesh="m_h_piston_r" />
                        <body name="b_h_cyl_r" pos="0 0.00495 -0.046739">
                            <!-- pos="0.0545 -0.05 -0.32" -->
                            <inertial pos="-0.000226861 -0.0195357 0.115677" quat="0.997923 0.0627685 0.00397027 -0.0139205" mass="0.325584" diaginertia="0.00201416 0.00189518 0.000287654" />
                            <joint name="j_H_LIN_R" pos="0 0 0" axis="0 -0.10531 0.994439" type="slide" limited="true" range="-0.0905355 0.0151645" damping="30" />
                            <geom name="g_h_cyl_r" pos="0.144495 0.05475 0.473995" type="mesh" mesh="m_h_cyl_r" rgba="0 0 0.5 0.3" />
                            <body name="b_thigh_r" pos="-0.0545 0.05 0.32">
                                <!-- pos="-0.055 -0.034 -0.055" -->
                                <inertial pos="0.0545 -0.0199022 -0.178756" quat="0.70582 -0.0426418 0.0426418 0.70582" mass="1.91939" diaginertia="0.0232006 0.020492 0.00736143" />
                                <joint name="j_Rev90_h_cyl_l" pos="0.0545 -0.05 -0.32" axis="1 0 0" type="hinge" />
                                <geom name="g_thigh_r" pos="0.198995 0.00475 0.153995" type="mesh" mesh="m_thigh_r" />
                                <body name="b_knee_pitch_weld_r" pos="0.0545 0 -0.375">
                                    <joint name="j_Knee_R" pos="0 0 0" axis="1 0 0" type="hinge" />
                                    <geom name="g_knee_pitch_weld_r" type="box" size=".01 .02 .03" rgba="0 1 1 .1" mass="0.000001" />
                                </body>
                                <body name="b_weld_h_pitch_r">
                                    <joint name="j_HPitch_R" type="hinge" axis="1 0 0" />
                                    <geom name="g_weld_h_pitch_r" type="box" size=".01 .02 .03" rgba="0 1 1 .1" mass="0.000001" />
                                </body>
                                <body name="b_k_cyl_r" pos="0.0545 -0.002 -0.125">
                                    <inertial pos="-2.96762e-05 0.0208376 -0.0951231" quat="0.997129 0.0757158 -0.00054397 0.000623813" mass="0.285571" diaginertia="0.001252 0.00113816 0.000253836" />
                                    <joint name="j_Rev86_k_cyl_r" pos="0 0 0" axis="-1 0 0" type="hinge" />
                                    <geom name="g_k_cyl_r" pos="0.144495 0.00675 0.278995" type="mesh" mesh="m_k_cyl_r" rgba="0 0 0.5 0.3" />
                                    <body name="b_k_piston_r" pos="0 0.006587 -0.046536">
                                        <inertial pos="-6.49445e-05 0.0201422 -0.142346" quat="0.996856 0.0697515 0.00379265 -0.0373886" mass="0.126617" diaginertia="0.000447013 0.000445151 2.48358e-05" />
                                        <joint name="j_K_LIN_R" pos="0 0 0" axis="0 -0.140141 0.990132" type="slide" limited="true" range="-0.077441 0.0" />
                                        <geom name="g_k_piston_r" pos="0.144495 0.000163 0.325531" type="mesh" mesh="m_k_piston_r" />
                                        <body name="b_calf_r" pos="0 -0.004587 -0.203464">
                                            <!-- pos="0 0 -0.375" -->
                                            <inertial pos="-3.92593e-05 -0.0104904 -0.134459" quat="0.706684 0.0199592 -0.0201719 0.70696" mass="1.72048" diaginertia="0.0250869 0.023294 0.00586012" />
                                            <joint name="j_knee_piston_conn_r" pos="0 0.039 -0.038" axis="1 0 0" type="hinge" />
                                            <geom name="g_calf_r" pos="0.144495 0.00475 0.528995" type="mesh" mesh="m_calf_r" rgba="0 0 0 .1" />
                                            <body name="b_acyl_ri" pos="0.0205 -0.03 -0.06">
                                                <inertial pos="-1.47058e-05 0.0247397 -0.0673517" quat="0.996501 -0.0835866 0 0" mass="0.128787" diaginertia="0.000369 0.000268055 0.000121945" />
                                                <joint name="j_Rev28_acyl_ri" pos="0 0 0" axis="-1 0 0" type="hinge" />
                                                <geom name="g_acyl_ri" pos="0.123995 0.03475 0.588995" type="mesh" mesh="m_acyl_ri" rgba="0 0 0.5 0.3" />
                                                <body name="b_a_piston_ri" pos="0 0.002203 -0.032425">
                                                    <inertial pos="5.42903e-05 0.00522392 -0.0768887" quat="0.999465 0.032701 0 0" mass="0.0378377" diaginertia="8e-05 7.93275e-05 2.67246e-06" />
                                                    <joint name="j_APITCH_RI" pos="0 0 0" axis="0 -0.067772 0.997701" type="slide" limited="true" range="-0.0115435 0.0274565" damping="30" />
                                                    <geom name="g_a_piston_ri" pos="0.123995 0.032547 0.62142" type="mesh" mesh="m_a_piston_ri" />
                                                    <body name="b_crank_ri" pos="0 0.051958 -0.157575">
                                                        <!-- pos="0.0205 0.024161 -0.25" -->
                                                        <inertial pos="5.06332e-08 -0.0363894 -0.000874521" quat="0.671365 0.741127 0 0" mass="0.0576547" diaginertia="7.6e-05 7.35941e-05 1.24059e-05" />
                                                        <joint name="j_Rev72_crank_ri" pos="0 -0.0423 0.0154" axis="1 0 0" type="hinge" />
                                                        <geom name="g_crank_ri" pos="0.123995 -0.019411 0.778995" type="mesh" mesh="m_crank_ri" />
                                                        <body name="b_crank_weld_ri" pos="0 0 0">
                                                            <joint name="j_crank_weld_ri" pos="0 0 0" axis="1 0 0" type="hinge" />
                                                            <geom name="g_crank_weld_ri" type="box" size=".01 .02 .03" rgba="0 1 1 .1" mass="0.000001" />
                                                        </body>
                                                        <body name="b_inner_weld_tf_ri" pos="0 -0.089434 -0.010081">
                                                            <joint name="j_inner_weld_tf_ri" type="hinge" axis="0 1 0" />
                                                            <geom name="g_inner_weld_tf_ri" type="sphere" size="0.01" rgba=" 0 1 0 .4" />
                                                            <body name="b_tf_ri" pos="0 0 0">
                                                                <inertial pos="5.10338e-08 -0.00232074 -0.0699611" quat="0.999844 -0.0176465 0 0" mass="0.0807558" diaginertia="0.000213 0.000207247 8.75283e-06" />
                                                                <joint name="j_Rev73_tf_ri" pos="0 0 0" axis="1 0 0" type="hinge" />
                                                                <geom name="g_tf_ri" pos="0.123995 0.070023 0.789076" type="mesh" mesh="m_tf_ri" />
                                                                <body name="b_outer_weld_tf_ri" pos="0 -0.0047 -0.14">
                                                                    <joint name="j_outer_weld_tf_ri" type="hinge" axis="0 1 0" />
                                                                    <geom name="g_outer_weld_tf_i" type="sphere" size="0.01" rgba=" 0 1 0 .4" />
                                                                    <!-- <geom name="g_weld_tf_li" pos="0 0 0" euler="0 1.57 0" type="cylinder" size="0.01 0.02" rgba=" 0 1 0 .4" /> -->
                                                                    <body name="b_weld_tf_ri" pos="0 0 0">
                                                                        <joint name="j_weld_tf_ri" type="hinge" axis="1 0 0" />
                                                                        <geom name="g_weld_tf_i" type="sphere" size="0.01" rgba=" 0 1 0 .4" />
                                                                        <!-- <geom name="g_weld_tf_li" pos="0 0 0" euler="0 1.57 0" type="cylinder" size="0.01 0.02" rgba=" 0 1 0 .4" /> -->
                                                                    </body>
                                                                </body>
                                                            </body>
                                                        </body>
                                                    </body>
                                                </body>
                                            </body>

                                            <body name="b_acyl_ro" pos="-0.0205 -0.03 -0.06">
                                                <inertial pos="-1.47058e-05 0.0247397 -0.0673517" quat="0.996501 -0.0835866 0 0" mass="0.128787" diaginertia="0.000369 0.000268055 0.000121945" />
                                                <joint name="j_Rev29_acyl_ro" pos="0 0 0" axis="-1 0 0" type="hinge" />
                                                <geom name="g_acyl_ro" pos="0.164995 0.03475 0.588995" type="mesh" mesh="m_acyl_ro" rgba="0 0 0.5 0.3" />
                                                <body name="b_a_piston_ro" pos="0 0.002203 -0.032425">
                                                    <inertial pos="5.42903e-05 0.00522387 -0.0768887" quat="0.999465 0.032701 0 0" mass="0.0378377" diaginertia="8e-05 7.93275e-05 2.67246e-06" />
                                                    <joint name="j_APITCH_RO" pos="0 0 0" axis="0 -0.067772 0.997701" type="slide" limited="true" range="-0.0115435 0.0274565" damping="30" />
                                                    <geom name="g_a_piston_ro" pos="0.164995 0.032547 0.62142" type="mesh" mesh="m_a_piston_ro" />
                                                    <body name="b_crank_ro" pos="0 0.051958 -0.157575">
                                                        <!-- pos="-0.0205 0.024161 -0.25" -->
                                                        <inertial pos="5.06332e-08 -0.0363894 -0.000874521" quat="0.671365 0.741127 0 0" mass="0.0576547" diaginertia="7.6e-05 7.35941e-05 1.24059e-05" />
                                                        <joint name="j_Rev75_crank_ro" pos="0 -0.0423 0.0154" axis="-1 0 0" type="hinge" />
                                                        <geom name="g_crank_ro" pos="0.164995 -0.019411 0.778995" type="mesh" mesh="m_crank_ro" />
                                                        <body name="b_crank_weld_ro" pos="0 0 0">
                                                            <joint name="j_crank_weld_ro" pos="0 0 0" axis="-1 0 0" type="hinge" />
                                                            <geom name="g_crank_weld_ro" type="box" size=".01 .02 .03" rgba="0 1 1 .1" mass="0.000001" />
                                                        </body>
                                                        <body name="b_inner_weld_tf_ro" pos="0 -0.089434 -0.010081">
                                                            <joint name="j_inner_weld_tf_ro" type="hinge" axis="0 1 0" />
                                                            <geom name="g_inner_weld_tf_ro" type="sphere" size="0.01" rgba=" 0 1 0 .4" />
                                                            <body name="b_tf_ro" pos="0 0 0">
                                                                <inertial pos="5.10338e-08 -0.00232074 -0.0699611" quat="0.999844 -0.0176465 0 0" mass="0.0807558" diaginertia="0.000213 0.000207247 8.75283e-06" />
                                                                <joint name="j_Rev74_tf_ro" pos="0 0 0" axis="-1 0 0" type="hinge" />
                                                                <geom name="g_tf_ro" pos="0.164995 0.070023 0.789076" type="mesh" mesh="m_tf_ro" />
                                                                <body name="b_outer_weld_tf_ro" pos="0 -0.0047 -0.14">
                                                                    <joint name="j_outer_weld_tf_ro" type="hinge" axis="-1 0 0" />
                                                                    <geom name="g_outer_weld_tf_ro" type="sphere" size="0.01" rgba=" 0 1 0 .4" />
                                                                    <!-- <geom name="g_weld_tf_lo" pos="0 0 0" euler="0 1.57 0" type="cylinder" size="0.01 0.02" rgba=" 0 1 0 .4" /> -->
                                                                    <body name="b_weld_tf_ro" pos="0 0 0">
                                                                        <joint name="j_weld_tf_ro" type="hinge" axis="0 1 0" />
                                                                        <geom name="g_weld_tf_ro" type="sphere" size="0.01" rgba=" 0 1 0 .4" />
                                                                        <!-- <geom name="g_weld_tf_lo" pos="0 0 0" euler="0 1.57 0" type="cylinder" size="0.01 0.02" rgba=" 0 1 0 .4" /> -->
                                                                    </body>
                                                                </body>
                                                            </body>
                                                        </body>
                                                    </body>
                                                </body>
                                            </body>
                                            <body name="b_a_commutator_r" pos="0 0 -0.4">
                                                <inertial pos="5.06339e-08 0 5.06339e-08" quat="0 0.707107 0 0.707107" mass="0.0528451" diaginertia="2.7e-05 1.7e-05 1.5e-05" />
                                                <joint name="j_APitch_R" pos="0 0 0" axis="1 0 0" type="hinge" limited="true" range="-0.2 0.2" />
                                                <geom name="g_a_commutator_r" pos="0.144495 0.00475 0.928995" type="mesh" mesh="m_a_commutator_r" />
                                                <body name="b_foot_r" pos="0 0 0">
                                                    <inertial pos="-0.000690715 -0.0558992 -0.0396184" quat="0.474068 0.512834 -0.5203 0.491476" mass="0.442363" diaginertia="0.00208294 0.00191408 0.000358977" />
                                                    <joint name="j_ARoll_R" pos="0 0 0" axis="0 -1 0" type="hinge" limited="true" range="-0.2 0.2" />
                                                    <geom name="g_foot_r" pos="0.144495 0.00475 0.928995" type="mesh" mesh="m_foot_r" />
                                                </body>
                                            </body>
                                        </body>
                                    </body>
                                </body>
                            </body>
                        </body>
                    </body>
                </body>
            </body>
        </body>

        <!-- HUMANOID -->
        <body name="b_root_1" pos="1.5 0 0" euler="0 -1.57079633 -1.57079633">
            <!-- <joint name="j_root_1" type="free" /> -->
            <geom name="g_root_1" pos="0 0.0746667 0" type="sphere" size="0.096" rgba="0 0 1 0.5" />
            <body name="b_chest_1" pos="0 0.2518944 0">
                <joint name="j_chest_1" pos="0 0 0" type="ball" />
                <geom name="g_chest_1" pos="0 0.128 0" type="sphere" size="0.117333" rgba="0 1 0 0.5" />
                <body name="b_neck_1" pos="0 0.238820267 0">
                    <joint name="j_neck_1" pos="0 0 0" type="ball" />
                    <geom name="g_neck_1" pos="0 0.18667 0" type="sphere" size="0.109333" rgba="1 0 0 0.5" />
                </body>
                <body name="b_right_shoulder_1" pos="-.0256533 0.259733 0.19531733">
                    <joint name="j_b_right_shoulder_1" pos="0 0 0" type="ball" />
                    <geom name="g_right_shoulder_1" pos="0 -0.14933 0" quat="0.707107 -0.707107 0 0" type="capsule" size="0.048 0.096" />
                    <body name="b_right_elbow_1" pos="0 -0.2931066 0">
                        <joint name="j_right_elbow_1" pos="0 0 0" axis="0 0 1" limited="true" range="0 3.14" />
                        <geom name="g_right_elbow_1" pos="0 -0.128 0" quat="0.707107 -0.707107 0 0" type="capsule" size="0.04266 0.072" />
                        <body name="b_right_wrist_1" pos="0 -0.27621066 0">
                            <geom name="g_right_wrist_1" type="sphere" size="0.04266" rgba="0 1 0 0.5" />
                        </body>
                    </body>
                </body>
                <body name="b_left_shoulder_1" pos="-0.0256533 0.259733 -0.19531733">
                    <joint name="j_left_shoulder_1" pos="0 0 0" type="ball" />
                    <geom name="g_left_shoulder_1" pos="0 -0.14933 0" quat="0.707107 -0.707107 0 0" type="capsule" size="0.048 0.096" />
                    <body name="b_left_elbow_1" pos="0 -0.2931066 0">
                        <joint name="j_left_elbow_1" pos="0 0 0" axis="0 0 1" limited="true" range="0 3.14" />
                        <geom name="g_left_elbow_1" pos="0 -0.128 0" quat="0.707107 -0.707107 0 0" type="capsule" size="0.04266 0.072" />
                        <body name="b_left_wrist_1" pos="0 -0.27621066 0">
                            <geom name="g_left_wrist_1" type="sphere" size="0.04266" rgba="0 1 0 0.5" />
                        </body>
                    </body>
                </body>
            </body>
            <body name="b_right_hip_1" pos="0 0 0.090546133">
                <joint name="j_right_hip_1" pos="0 0 0" type="ball" />
                <geom name="g_right_hip_1" pos="0 -0.224 0" quat="0.707107 -0.707107 0 0" type="capsule" size="0.05866 0.16" />
                <body name="b_right_knee_1" pos="0 -0.449648 0">
                    <joint name="j_right_knee_1" pos="0 0 0" axis="0 0 1" limited="true" range="-3.14 0" />
                    <geom name="g_right_knee_1" pos="0 -0.2133 0" quat="0.707107 -0.707107 0 0" type="capsule" size="0.0533 0.16533" />
                    <body name="b_right_ankle_1" pos="0 -0.43719466 0">
                        <joint name="j_right_ankle_1" pos="0 0 0" type="ball" />
                        <geom name="g_right_ankle_1" pos="0.048 -0.024 0" type="box" size="0.0944 0.02933 0.048" rgba="0 1 0 0.5" />
                    </body>
                </body>
            </body>
            <body name="b_left_hip_1" pos="0 0 -0.090546133">
                <joint name="j_left_hip_1" pos="0 0 0" type="ball" />
                <geom name="g_left_hip_1" pos="0 -0.224 0" quat="0.707107 -0.707107 0 0" type="capsule" size="0.05866 0.16" />
                <body name="b_left_knee_1" pos="0 -0.449648 0">
                    <joint name="j_left_knee_1" pos="0 0 0" axis="0 0 1" limited="true" range="-3.14 0" />
                    <geom name="g_left_knee_1" pos="0 -0.2133 0" quat="0.707107 -0.707107 0 0" type="capsule" size="0.0533 0.16533" />
                    <body name="b_left_ankle_1" pos="0 -0.43719466 0">
                        <joint name="j_left_ankle_1" pos="0 0 0" type="ball" />
                        <geom name="g_left_ankle_1" pos="0.048 -0.024 0" type="box" size="0.0944 0.02933 0.048" rgba="0 1 0 0.5" />
                    </body>
                </body>
            </body>
        </body>
    </worldbody>

    <equality>
        <!-- MOCAP WELD: RJAX -->
        <!-- <weld name="wrist_r" body1="mocap_wrist_r" body2="b_end_arm_r" />
        <weld name="wrist_l" body1="mocap_wrist_l" body2="b_end_arm_l" />
        <weld name="ankle_point_l" body1="mocap_ankle_point_l" body2="b_a_commutator_l" />
        <weld name="ankle_point_r" body1="mocap_ankle_point_r" body2="b_a_commutator_r" /> -->

        <!-- <weld name="elbow_point_r" body1="mocap_elbow_point_r" body2="b_s_yaw_r" /> -->
        <!-- <weld name="elbow_point_l" body1="mocap_elbow_point_l" body2="b_s_yaw_l" /> -->


        <weld name="weld_epitch_l" body1="b_end_arm_l" body2="b_weld_epitch_l" relpose="0 0 0 1 0 0 0" solref="0.0002 1" />
        <weld name="weld_epitch_r" body1="b_end_arm_r" body2="b_weld_epitch_r" relpose="0 0 0 1 0 0 0" solref="0.0002 1" />
        <!-- relpose="-0.014241 -0.0121 -0.3296 1 0 0 0" -->

        <weld name="weld_hpitch_l" body1="b_hip_yaw_l" body2="b_weld_h_pitch_l" relpose="0.055 -0.034 -0.055 1 0 0 0" solref="0.0002 1" />
        <weld name="weld_hpitch_r" body1="b_hip_yaw_r" body2="b_weld_h_pitch_r" relpose="-0.055 -0.034 -0.055 1 0 0 0" solref="0.0002 1" />
        <weld name="weld_kpitch_l" body1="b_calf_l" body2="b_knee_pitch_weld_l" relpose="0 0 0 1 0 0 0" solref="0.0002 1" />
        <weld name="weld_kpitch_r" body1="b_calf_r" body2="b_knee_pitch_weld_r" relpose="0 0 0 1 0 0 0" solref="0.0002 1" />

        <weld name="weld_apitch_lo" body1="b_calf_l" body2="b_crank_weld_lo" relpose="0.0205 0.024161 -0.25 1 0 0 0" solref="0.0002 1" />
        <weld name="weld_apitch_li" body1="b_calf_l" body2="b_crank_weld_li" relpose="-0.0205 0.024161 -0.25 1 0 0 0" solref="0.0002 1" />
        <weld name="weld_a_tf_lo" body1="b_foot_l" body2="b_weld_tf_lo" relpose="0.0205 -0.07 0 1 0 0 0" solref="0.0002 1" />
        <weld name="weld_a_tf_li" body1="b_foot_l" body2="b_weld_tf_li" relpose="-0.0205 -0.07 0 1 0 0 0" solref="0.0002 1" />

        <weld name="weld_apitch_ro" body1="b_calf_r" body2="b_crank_weld_ro" relpose="0.0205 0.024161 -0.25 1 0 0 0" solref="0.0002 1" />
        <weld name="weld_apitch_ri" body1="b_calf_r" body2="b_crank_weld_ri" relpose="-0.0205 0.024161 -0.25 1 0 0 0" solref="0.0002 1" />
        <weld name="weld_a_tf_ro" body1="b_foot_r" body2="b_weld_tf_ro" relpose="-0.0205 -0.07 0 1 0 0 0" solref="0.0002 1" />
        <weld name="weld_a_tf_ri" body1="b_foot_r" body2="b_weld_tf_ri" relpose="0.0205 -0.07 0 1 0 0 0" solref="0.0002 1" />
    </equality>

    <actuator>
        <!-- SHOULDERS -->
        <position name="pos_act_j_SPitch_L" joint="j_SPitch_L" kp="100" forcelimited="true" forcerange="-130 130" />
        <position name="pos_act_j_SRoll_L" joint="j_SRoll_L" kp="100" forcelimited="true" forcerange="-130 130" />
        <position name="pos_act_j_SYaw_L" joint="j_SYaw_L" kp="100" forcelimited="true" forcerange="-70 70" />
        <position name="pos_act_j_SPitch_R" joint="j_SPitch_R" kp="100" forcelimited="true" forcerange="-130 130" />
        <position name="pos_act_j_SRoll_R" joint="j_SRoll_R" kp="100" forcelimited="true" forcerange="-130 130" />
        <position name="pos_act_j_SYaw_R" joint="j_SYaw_R" kp="100" forcelimited="true" forcerange="-70 70" />

        <!-- TOROSO -->
        <position name="pos_act_j_TYaw" joint="j_TYaw" kp="100" forcelimited="true" forcerange="-70 70" />
        <position name="pos_act_j_TRoll" joint="j_TRoll" kp="500" forcelimited="true" forcerange="-70 70" />

        <!-- HIP -->
        <position name="pos_act_j_HRoll_L" joint="j_HRoll_L" kp="1000" forcelimited="true" forcerange="-130 130" />
        <position name="pos_act_j_HYaw_L" joint="j_HYaw_L" kp="500" forcelimited="true" forcerange="-70 70" />
        <position name="pos_act_j_HRoll_R" joint="j_HRoll_R" kp="1000" forcelimited="true" forcerange="-130 130" />
        <position name="pos_act_j_HYaw_R" joint="j_HYaw_R" kp="500" forcelimited="true" forcerange="-70 70" />

        <!-- HIP PITCH LIN Bore: 50mm Rod: 22mm -->
        <cylinder name="pos_act_j_HPitch_L" joint="j_H_LIN_L" timeconst="1" diameter="2" forcelimited="true" forcerange="-1500 1900" ctrlrange="-504.0 625.0" ctrllimited="true" />
        <cylinder name="pos_act_j_HPitch_R" joint="j_H_LIN_R" timeconst="1" diameter="2" forcelimited="true" forcerange="-1500 1900" ctrlrange="-504.0 625.0" ctrllimited="true" />

        <!-- KNEE PITCH LIN Bore: 50mm Rod: 22mm -->
        <cylinder name="pos_act_j_Knee_L" joint="j_K_LIN_L" timeconst="1" diameter="2" forcelimited="true" forcerange="-1900 1500" ctrlrange="-625.0 504.0" ctrllimited="true" />
        <cylinder name="pos_act_j_Knee_R" joint="j_K_LIN_R" timeconst="1" diameter="2" forcelimited="true" forcerange="-1900 1500" ctrlrange="-625.0 504.0" ctrllimited="true" />

        <!-- ELBOW PITCH LIN Bore: 40mm Rod: 18mm -->
        <cylinder name="pos_act_j_EPitch_L" joint="j_E_LIN_L" timeconst="1" diameter="2" forcelimited="false" forcerange="-800 300" ctrlrange="-400.0 319.0" ctrllimited="true" />
        <cylinder name="pos_act_j_EPitch_R" joint="j_E_LIN_R" timeconst="1" diameter="2" forcelimited="false" forcerange="-800 300" ctrlrange="-400.0 319.0" ctrllimited="true" />

        <!-- ANKLE COMBINED LIN Bore: 25mm Rod: 16mm  -->
        <cylinder name="pos_act_j_APITCH_LO" joint="j_APITCH_LO" timeconst="1" diameter="2" forcelimited="true" forcerange="-400 200" ctrlrange="-156.25 92.25" ctrllimited="true" />
        <cylinder name="pos_act_j_APITCH_LI" joint="j_APITCH_LI" timeconst="1" diameter="2" forcelimited="true" forcerange="-400 200" ctrlrange="-156.25 92.25" ctrllimited="true" />
        <cylinder name="pos_act_j_APITCH_RO" joint="j_APITCH_RO" timeconst="1" diameter="2" forcelimited="true" forcerange="-400 200" ctrlrange="-156.25 92.25" ctrllimited="true" />
        <cylinder name="pos_act_j_APITCH_RI" joint="j_APITCH_RI" timeconst="1" diameter="2" forcelimited="true" forcerange="-400 200" ctrlrange="-156.25 92.25" ctrllimited="true" />

    </actuator>

    <sensor>
        <jointpos name="pos_sensor_j_TYaw" joint="j_TYaw" />
        <jointpos name="pos_sensor_j_TRoll" joint="j_TRoll" />
        <jointpos name="pos_sensor_j_SPitch_L" joint="j_SPitch_L" />
        <jointpos name="pos_sensor_j_SRoll_L" joint="j_SRoll_L" />
        <jointpos name="pos_sensor_j_SYaw_L" joint="j_SYaw_L" />
        <jointpos name="pos_sensor_j_EPitch_L" joint="j_EPitch_L" />
        <jointpos name="pos_sensor_j_SPitch_R" joint="j_SPitch_R" />
        <jointpos name="pos_sensor_j_SRoll_R" joint="j_SRoll_R" />
        <jointpos name="pos_sensor_j_SYaw_R" joint="j_SYaw_R" />
        <jointpos name="pos_sensor_j_EPitch_R" joint="j_EPitch_R" />
        <jointpos name="pos_sensor_j_HRoll_L" joint="j_HRoll_L" />
        <jointpos name="pos_sensor_j_HYaw_L" joint="j_HYaw_L" />
        <jointpos name="pos_sensor_j_HPitch_L" joint="j_HPitch_L" />
        <jointpos name="pos_sensor_j_Knee_L" joint="j_Knee_L" />
        <jointpos name="pos_sensor_j_HRoll_R" joint="j_HRoll_R" />
        <jointpos name="pos_sensor_j_HYaw_R" joint="j_HYaw_R" />
        <jointpos name="pos_sensor_j_HPitch_R" joint="j_HPitch_R" />
        <jointpos name="pos_sensor_j_Knee_R" joint="j_Knee_R" />
        <jointpos name="pos_sensor_j_APitch_L" joint="j_APitch_L" />
        <jointpos name="pos_sensor_j_ARoll_L" joint="j_ARoll_L" />
        <jointpos name="pos_sensor_j_APitch_R" joint="j_APitch_R" />
        <jointpos name="pos_sensor_j_ARoll_R" joint="j_ARoll_R" />
    </sensor>

    <!-- RJAX CONTACT PAIRS -->
    <contact>
        <!-- RJAX -->
        <!-- MAIN BODY -->
        <pair name="cp_torso_mid" geom1="g_plane" geom2="g_torso_mid" />
        <pair name="cp_main_body" geom1="g_plane" geom2="g_main_body" />
        <pair name="cp_base_link" geom1="g_plane" geom2="g_base_link" />
        <!-- HANDS -->
        <pair name="cp_s_pitch_l" geom1="g_plane" geom2="g_s_pitch_l" />
        <pair name="cp_s_pitch_r" geom1="g_plane" geom2="g_s_pitch_r" />
        <pair name="cp_s_adapter_l" geom1="g_plane" geom2="g_s_adapter_l" />
        <pair name="cp_s_adapter_r" geom1="g_plane" geom2="g_s_adapter_r" />
        <pair name="cp_s_roll_r" geom1="g_plane" geom2="g_s_roll_r" />
        <pair name="cp_s_roll_l" geom1="g_plane" geom2="g_s_roll_l" />
        <pair name="cp_s_yaw_l" geom1="g_plane" geom2="g_s_yaw_l" />
        <pair name="cp_s_yaw_r" geom1="g_plane" geom2="g_s_yaw_r" />
        <pair name="cp_end_arm_l" geom1="g_plane" geom2="g_end_arm_l" />
        <pair name="cp_end_arm_r" geom1="g_plane" geom2="g_end_arm_r" />
        <pair name="cp_e_cyl_l" geom1="g_plane" geom2="g_e_cyl_l" />
        <pair name="cp_e_cyl_r" geom1="g_plane" geom2="g_e_cyl_r" />
        <pair name="cp_e_piston_l" geom1="g_plane" geom2="g_e_piston_l" />
        <pair name="cp_e_piston_r" geom1="g_plane" geom2="g_e_piston_r" />
        <!-- LEGS -->
        <pair name="cp_leg_adapter_l" geom1="g_plane" geom2="g_leg_adapter_l" />
        <pair name="cp_leg_adapter_r" geom1="g_plane" geom2="g_leg_adapter_r" />
        <pair name="cp_hip_yaw_l" geom1="g_plane" geom2="g_hip_yaw_l" />
        <pair name="cp_hip_yaw_r" geom1="g_plane" geom2="g_hip_yaw_r" />
        <pair name="cp_thigh_l" geom1="g_plane" geom2="g_thigh_l" />
        <pair name="cp_thigh_r" geom1="g_plane" geom2="g_thigh_r" />
        <pair name="cp_k_cyl_l" geom1="g_plane" geom2="g_k_cyl_l" />
        <pair name="cp_k_cyl_r" geom1="g_plane" geom2="g_k_cyl_r" />
        <pair name="cp_k_piston_l" geom1="g_plane" geom2="g_k_piston_l" />
        <pair name="cp_k_piston_r" geom1="g_plane" geom2="g_k_piston_r" />
        <pair name="cp_h_cyl_l" geom1="g_plane" geom2="g_h_cyl_l" />
        <pair name="cp_h_cyl_r" geom1="g_plane" geom2="g_h_cyl_r" />
        <pair name="cp_h_piston_l" geom1="g_plane" geom2="g_h_piston_l" />
        <pair name="cp_h_piston_r" geom1="g_plane" geom2="g_h_piston_r" />
        <!-- CALF -->
        <pair name="cp_calf_l" geom1="g_plane" geom2="g_calf_l" />
        <pair name="cp_calf_r" geom1="g_plane" geom2="g_calf_r" />
        <pair name="cp_acyl_li" geom1="g_plane" geom2="g_acyl_li" />
        <pair name="cp_acyl_ri" geom1="g_plane" geom2="g_acyl_ri" />
        <pair name="cp_acyl_lo" geom1="g_plane" geom2="g_acyl_lo" />
        <pair name="cp_acyl_ro" geom1="g_plane" geom2="g_acyl_ro" />
        <pair name="cp_a_piston_li" geom1="g_plane" geom2="g_a_piston_li" />
        <pair name="cp_a_piston_lo" geom1="g_plane" geom2="g_a_piston_lo" />
        <pair name="cp_a_piston_ri" geom1="g_plane" geom2="g_a_piston_ri" />
        <pair name="cp_a_piston_ro" geom1="g_plane" geom2="g_a_piston_ro" />
        <pair name="cp_crank_lo" geom1="g_plane" geom2="g_crank_lo" />
        <pair name="cp_crank_li" geom1="g_plane" geom2="g_crank_li" />
        <pair name="cp_crank_ro" geom1="g_plane" geom2="g_crank_ro" />
        <pair name="cp_crank_ri" geom1="g_plane" geom2="g_crank_ri" />
        <pair name="cp_tf_lo" geom1="g_plane" geom2="g_tf_lo" />
        <pair name="cp_tf_li" geom1="g_plane" geom2="g_tf_li" />
        <pair name="cp_tf_ro" geom1="g_plane" geom2="g_tf_ro" />
        <pair name="cp_tf_ri" geom1="g_plane" geom2="g_tf_ri" />
        <!-- FEET -->
        <pair name="cp_a_commutator_l" geom1="g_plane" geom2="g_a_commutator_l" />
        <pair name="cp_a_commutator_r" geom1="g_plane" geom2="g_a_commutator_r" />
        <pair name="cp_foot_l" geom1="g_plane" geom2="g_foot_l" />
        <pair name="cp_foot_r" geom1="g_plane" geom2="g_foot_r" />
        <!-- <pair name="cp_foot_l_collision" geom1="g_collision_box" geom2="g_foot_l" /> -->
        <!-- <pair name="cp_foot_r_collision" geom1="g_collision_box" geom2="g_foot_r" /> -->
    </contact>

    <!-- HUMANOID CONTACT PAIRS -->
    <contact>
        <!-- HUMANOID -->
        <!-- MAIN BODY -->
        <pair name="cp_root_1" geom1="g_plane" geom2="g_root_1" />
        <pair name="cp_chest_1" geom1="g_plane" geom2="g_chest_1" />
        <pair name="cp_neck_1" geom1="g_plane" geom2="g_neck_1" />
        <!-- ARMS -->
        <pair name="cp_right_shoulder_1" geom1="g_plane" geom2="g_right_shoulder_1" />
        <pair name="cp_left_shoulder_1" geom1="g_plane" geom2="g_left_shoulder_1" />
        <pair name="cp_right_elbow_1" geom1="g_plane" geom2="g_right_elbow_1" />
        <pair name="cp_left_elbow_1" geom1="g_plane" geom2="g_left_elbow_1" />
        <pair name="cp_right_wrist_1" geom1="g_plane" geom2="g_right_wrist_1" />
        <pair name="cp_left_wrist_1" geom1="g_plane" geom2="g_left_wrist_1" />
        <!-- LEGS -->
        <pair name="cp_right_hip_1" geom1="g_plane" geom2="g_right_hip_1" />
        <pair name="cp_left_hip_1" geom1="g_plane" geom2="g_left_hip_1" />
        <pair name="cp_right_knee_1" geom1="g_plane" geom2="g_right_knee_1" />
        <pair name="cp_left_knee_1" geom1="g_plane" geom2="g_left_knee_1" />
        <pair name="cp_right_ankle_1" geom1="g_plane" geom2="g_right_ankle_1" />
        <pair name="cp_left_ankle_1" geom1="g_plane" geom2="g_left_ankle_1" />
    </contact>

</mujoco>